<?xml version="1.0" encoding="UTF-8"?>
<!-- Generated by org.testng.reporters.JUnitReportReporter -->
<testsuite hostname="DESKTOP-248P7JL" failures="1" tests="3" name="test.EntrataTest" time="52.832" errors="0" timestamp="2024-09-22T19:03:03 IST" skipped="0">
  <testcase classname="test.EntrataTest" name="verifyProductListOfEntrataWebsite" time="13.298"/>
  <testcase classname="test.EntrataTest" name="verifyScheduleDemoFormForEntrataWebsite" time="15.779"/>
  <testcase classname="test.EntrataTest" name="verifyAlreadyRegisterFUnctionalityWithIncorrectDetails" time="23.755">
    <failure message="expected [This confirmation number doesn&#039;t exist.] but found [You&#039;ve reached your maximum number of login attempts. Contact the event planner to continue.]" type="java.lang.AssertionError">
      <![CDATA[java.lang.AssertionError: expected [This confirmation number doesn't exist.] but found [You've reached your maximum number of login attempts. Contact the event planner to continue.]
at org.testng.Assert.fail(Assert.java:111)
at org.testng.Assert.failNotEquals(Assert.java:1578)
at org.testng.Assert.assertEqualsImpl(Assert.java:150)
at org.testng.Assert.assertEquals(Assert.java:132)
at org.testng.Assert.assertEquals(Assert.java:656)
at org.testng.Assert.assertEquals(Assert.java:666)
at test.EntrataTest.verifyAlreadyRegisterFUnctionalityWithIncorrectDetails(EntrataTest.java:138)
at java.base/jdk.internal.reflect.NativeMethodAccessorImpl.invoke0(Native Method)
at java.base/jdk.internal.reflect.NativeMethodAccessorImpl.invoke(NativeMethodAccessorImpl.java:77)
at java.base/jdk.internal.reflect.DelegatingMethodAccessorImpl.invoke(DelegatingMethodAccessorImpl.java:43)
at java.base/java.lang.reflect.Method.invoke(Method.java:568)
at org.testng.internal.invokers.MethodInvocationHelper.invokeMethod(MethodInvocationHelper.java:141)
at org.testng.internal.invokers.TestInvoker.invokeMethod(TestInvoker.java:686)
at org.testng.internal.invokers.TestInvoker.invokeTestMethod(TestInvoker.java:230)
at org.testng.internal.invokers.MethodRunner.runInSequence(MethodRunner.java:63)
at org.testng.internal.invokers.TestInvoker$MethodInvocationAgent.invoke(TestInvoker.java:992)
at org.testng.internal.invokers.TestInvoker.invokeTestMethods(TestInvoker.java:203)
at org.testng.internal.invokers.TestMethodWorker.invokeTestMethods(TestMethodWorker.java:154)
at org.testng.internal.invokers.TestMethodWorker.run(TestMethodWorker.java:134)
at java.base/java.util.concurrent.Executors$RunnableAdapter.call(Executors.java:539)
at java.base/java.util.concurrent.FutureTask.run(FutureTask.java:264)
at org.testng.internal.thread.graph.TestNGFutureTask.run(TestNGFutureTask.java:22)
at java.base/java.util.concurrent.ThreadPoolExecutor.runWorker(ThreadPoolExecutor.java:1136)
at java.base/java.util.concurrent.ThreadPoolExecutor$Worker.run(ThreadPoolExecutor.java:635)
at java.base/java.lang.Thread.run(Thread.java:842)
]]>
    </failure>
  </testcase> <!-- verifyAlreadyRegisterFUnctionalityWithIncorrectDetails -->
</testsuite> <!-- test.EntrataTest -->
